<?xml version="1.0" ?>
<robot name="robot1">
    <!-- Import Rviz colors -->
    <material name="Black">
        <color rgba="0.0 0.0 0.0 1.0"/>
    </material>
    <material name="Blue">
        <color rgba="0.0 0.0 0.8 1.0"/>
    </material>
    <material name="Green">
        <color rgba="0.0 0.8 0.0 1.0"/>
    </material>
    <material name="Grey">
        <color rgba="0.4 0.4 0.4 1.0"/>
    </material>
    <material name="DarkGrey">
        <color rgba="0.3 0.3 0.3 1.0"/>
    </material>
    <material name="Orange">
        <color rgba="1.0 0.423529411765 0.0392156862745 1.0"/>
    </material>
    <material name="Brown">
        <color rgba="0.870588235294 0.811764705882 0.764705882353 1.0"/>
    </material>
    <material name="Red">
        <color rgba="0.8 0.0 0.0 1.0"/>
    </material>
    <material name="White">
        <color rgba="1.0 1.0 1.0 1.0"/>
    </material>

<!--
    ###################################################################################################################
    Not that all mass/inertial values are examples values only. They are not representative of the actual components.
    ###################################################################################################################

-->
    <link name="base_footprint">
        <inertial>
            <mass value="0.0001"/>
            <origin xyz="0 0 0"/>
            <inertia ixx="0.0001" ixy="0.0" ixz="0.0" iyy="0.0001" iyz="0.0" izz="0.0001"/>
        </inertial>
        <visual>
            <origin rpy="0 0 0" xyz="0 0 0"/>
            <geometry>
            <box size="0.001 0.001 0.001"/>
            </geometry>
        </visual>
    </link>
    <gazebo reference="base_footprint">
        <turnGravityOff>false</turnGravityOff>
    </gazebo>
    <joint name="base_footprint_joint" type="fixed">
        <origin rpy="0 0 0" xyz="0 0 0.04"/>
        <parent link="base_footprint"/>
        <child link="base_link"/>
    </joint>
    <!-- BASE-LINK -->
    <!--Actual body/chassis of the robot-->
    <link name="base_link">
        <inertial>
            <mass value="5"/>
            <origin xyz="0 0 0"/>
            <!--The 3x3 rotational inertia matrix. -->
            <inertia ixx="0.0282916666667" ixy="0" ixz="0" iyy="0.0282916666667" iyz="0" izz="0.05625"/>
        </inertial>
        <visual>
            <origin rpy="0 0 0" xyz="0 0 0"/>
            <geometry>
            <box size="0.25 0.25 0.05"/>
            <!-- <cylinder length="0.02" radius="0.15"/> -->
            </geometry>
            <material name="White"/>
        </visual>
        <collision>
            <origin rpy="0 0 0 " xyz="0 0 0"/>
            <geometry>
            <box size="0.25 0.25 0.05"/>
            <!-- <cylinder length="0.02" radius="0.15"/> -->
            </geometry>
        </collision>
    </link>
    <gazebo reference="base_link">
        <material>Gazebo/White</material>
        <turnGravityOff>false</turnGravityOff>
    </gazebo>
    <link name="front_right_wheel">
    <visual>
      <origin rpy="1.57079632679 0  0 " xyz="0 0 0"/>
      <geometry>
        <cylinder length="0.05" radius="0.05"/>
      </geometry>
      <material name="DarkGray"/>
    </visual>
    <collision>
      <origin rpy="1.57079632679 0 0 " xyz="0 0 0"/>
      <geometry>
        <cylinder length="0.05" radius="0.05"/>
      </geometry>
    </collision>
    <inertial>
      <mass value="2.5"/>
      <origin xyz="0 0 0"/>
      <inertia ixx="0.00108333333333" ixy="0" ixz="0" iyy="0.00108333333333" iyz="0" izz="0.002"/>
    </inertial>
  </link>
    <gazebo reference="front_right_wheel">
    <mu1 value="1.0"/>
    <mu2 value="1.0"/>
    <kp value="10000000.0"/>
    <kd value="1.0"/>
    <fdir1 value="1 0 0"/>
    <material>Gazebo/Black</material>
    <turnGravityOff>false</turnGravityOff>
    </gazebo>
    <joint name="front_right_wheel_joint" type="continuous">
    <parent link="base_link"/>
    <child link="front_right_wheel"/>
    <origin rpy="0 0 0" xyz="0.1 0.15 0.0"/>
    <axis rpy="0  0" xyz="0 1 0"/>
    <limit effort="100" velocity="100"/>
    <joint_properties damping="0.0" friction="0.0"/>
    </joint>
    <!-- Transmission is important to link the joints and the controller -->
    <transmission name="front_right_wheel_joint_trans">
    <type>transmission_interface/SimpleTransmission</type>
    <joint name="front_right_wheel_joint"/>
    <actuator name="front_right_wheel_joint_motor">
        <hardwareInterface>EffortJointInterface</hardwareInterface>
        <mechanicalReduction>1</mechanicalReduction>
    </actuator>
    </transmission>
    <!--fb : front, back ; lr: left, right -->
    <link name="front_left_wheel">
    <visual>
        <origin rpy="1.57079632679 0  0 " xyz="0 0 0"/>
        <geometry>
        <cylinder length="0.05" radius="0.05"/>
        </geometry>
        <material name="DarkGray"/>
    </visual>
    <collision>
        <origin rpy="1.57079632679 0 0 " xyz="0 0 0"/>
        <geometry>
        <cylinder length="0.05" radius="0.05"/>
        </geometry>
    </collision>
    <inertial>
        <mass value="2.5"/>
        <origin xyz="0 0 0"/>
        <inertia ixx="0.00108333333333" ixy="0" ixz="0" iyy="0.00108333333333" iyz="0" izz="0.002"/>
    </inertial>
    </link>
    <gazebo reference="front_left_wheel">
    <mu1 value="1.0"/>
    <mu2 value="1.0"/>
    <kp value="10000000.0"/>
    <kd value="1.0"/>
    <fdir1 value="1 0 0"/>
    <material>Gazebo/Black</material>
    <turnGravityOff>false</turnGravityOff>
    </gazebo>
    <joint name="front_left_wheel_joint" type="continuous">
    <parent link="base_link"/>
    <child link="front_left_wheel"/>
    <origin rpy="0 0 0" xyz="0.1 -0.15 0.0"/>
    <axis rpy="0  0" xyz="0 1 0"/>
    <limit effort="100" velocity="100"/>
    <joint_properties damping="0.0" friction="0.0"/>
    </joint>
    <!-- Transmission is important to link the joints and the controller -->
    <transmission name="front_left_wheel_joint_trans">
    <type>transmission_interface/SimpleTransmission</type>
    <joint name="front_left_wheel_joint"/>
    <actuator name="front_left_wheel_joint_motor">
        <hardwareInterface>EffortJointInterface</hardwareInterface>
        <mechanicalReduction>1</mechanicalReduction>
    </actuator>
    </transmission>

  <link name="hind_right_wheel">
    <visual>
      <origin rpy="1.57079632679 0  0 " xyz="0 0 0"/>
      <geometry>
        <cylinder length="0.05" radius="0.05"/>
      </geometry>
      <material name="DarkGray"/>
    </visual>
    <collision>
      <origin rpy="1.57079632679 0 0 " xyz="0 0 0"/>
      <geometry>
        <cylinder length="0.05" radius="0.05"/>
      </geometry>
    </collision>
    <inertial>
      <mass value="2.5"/>
      <origin xyz="0 0 0"/>
      <inertia ixx="0.00108333333333" ixy="0" ixz="0" iyy="0.00108333333333" iyz="0" izz="0.002"/>
    </inertial>
  </link>
    <gazebo reference="hind_right_wheel">
    <mu1 value="1.0"/>
    <mu2 value="1.0"/>
    <kp value="10000000.0"/>
    <kd value="1.0"/>
    <fdir1 value="1 0 0"/>
    <material>Gazebo/Black</material>
    <turnGravityOff>false</turnGravityOff>
    </gazebo>
    <joint name="hind_right_wheel_joint" type="continuous">
    <parent link="base_link"/>
    <child link="hind_right_wheel"/>
    <origin rpy="0 0 0" xyz="-0.1 0.15 0.0"/>
    <axis rpy="0  0" xyz="0 1 0"/>
    <limit effort="100" velocity="100"/>
    <joint_properties damping="0.0" friction="0.0"/>
    </joint>
    <!-- Transmission is important to link the joints and the controller -->
    <transmission name="hind_right_wheel_joint_trans">
    <type>transmission_interface/SimpleTransmission</type>
    <joint name="hind_right_wheel_joint"/>
    <actuator name="hind_right_wheel_joint_motor">
        <hardwareInterface>EffortJointInterface</hardwareInterface>
        <mechanicalReduction>1</mechanicalReduction>
    </actuator>
    </transmission>
    <!--fb : front, back ; lr: left, right -->
    <link name="hind_left_wheel">
    <visual>
        <origin rpy="1.57079632679 0  0 " xyz="0 0 0"/>
        <geometry>
        <cylinder length="0.05" radius="0.05"/>
        </geometry>
        <material name="DarkGray"/>
    </visual>
    <collision>
        <origin rpy="1.57079632679 0 0 " xyz="0 0 0"/>
        <geometry>
        <cylinder length="0.05" radius="0.05"/>
        </geometry>
    </collision>
    <inertial>
        <mass value="2.5"/>
        <origin xyz="0 0 0"/>
        <inertia ixx="0.00108333333333" ixy="0" ixz="0" iyy="0.00108333333333" iyz="0" izz="0.002"/>
    </inertial>
    </link>
    <gazebo reference="hind_left_wheel">
    <mu1 value="1.0"/>
    <mu2 value="1.0"/>
    <kp value="10000000.0"/>
    <kd value="1.0"/>
    <fdir1 value="1 0 0"/>
    <material>Gazebo/Black</material>
    <turnGravityOff>false</turnGravityOff>
    </gazebo>
    <joint name="hind_left_wheel_joint" type="continuous">
    <parent link="base_link"/>
    <child link="hind_left_wheel"/>
    <origin rpy="0 0 0" xyz="-0.1 -0.15 0.0"/>
    <axis rpy="0  0" xyz="0 1 0"/>
    <limit effort="100" velocity="100"/>
    <joint_properties damping="0.0" friction="0.0"/>
    </joint>
    <!-- Transmission is important to link the joints and the controller -->
    <transmission name="front_left_wheel_joint_trans">
    <type>transmission_interface/SimpleTransmission</type>
    <joint name="hind_left_wheel_joint"/>
    <actuator name="hind_left_wheel_joint_motor">
        <hardwareInterface>EffortJointInterface</hardwareInterface>
        <mechanicalReduction>1</mechanicalReduction>
    </actuator>
    </transmission>
    <link name="camera_link">
    <visual>
      <origin rpy="0 0 0" xyz="0 0 0"/>
      <geometry>
        <box size="0.05 0.05 0.05"/>
      </geometry>
      <material name="Blue"/>
    </visual>
  </link>
  <joint name="hokuyo_joint" type="fixed">
    <origin rpy="0 0 0" xyz="0.125 0 0.0325"/>
    <parent link="base_link"/>
    <child link="camera_link"/>
  </joint>
  <gazebo reference="camera_link">
        <material>Gazebo/Blue</material>
        <turnGravityOff>false</turnGravityOff>
        <sensor type="camera" name="camera1">
            <update_rate>30.0</update_rate>
            <camera name="head">
            <horizontal_fov>1.3962634</horizontal_fov>
            <image>
                <width>800</width>
                <height>800</height>
                <format>R8G8B8</format>
            </image>
            <clip>
                <near>0.02</near>
                <far>300</far>
            </clip>
            <noise>
                <type>gaussian</type>

                <mean>0.0</mean>
                <stddev>0.007</stddev>
            </noise>
            </camera>
            <plugin name="camera_controller" filename="libgazebo_ros_camera.so">
                <alwaysOn>true</alwaysOn>
                <updateRate>0.0</updateRate>
                <cameraName>robot1/camera1</cameraName>
                <imageTopicName>image_raw</imageTopicName>
                <cameraInfoTopicName>camera_info</cameraInfoTopicName>
                <frameName>camera_link</frameName>
                <hackBaseline>0.07</hackBaseline>
                <distortionK1>0.0</distortionK1>
                <distortionK2>0.0</distortionK2>
                <distortionK3>0.0</distortionK3>
                <distortionT1>0.0</distortionT1>
                <distortionT2>0.0</distortionT2>
            </plugin>
        </sensor>
    </gazebo>
    <!-- Differential drive controller 
  <gazebo>
    <plugin filename="libgazebo_ros_diff_drive.so" name="differential_drive_controller_front">
      <rosDebugLevel>Debug</rosDebugLevel>
      <publishWheelTF>True</publishWheelTF>
      <publishTf>1</publishTf>
      <publishWheelJointState>true</publishWheelJointState>
      <alwaysOn>true</alwaysOn>
      <updateRate>100.0</updateRate>
      <leftJoint>front_left_wheel_joint</leftJoint>
      <rightJoint>front_right_wheel_joint</rightJoint>
      <wheelSeparation>0.3</wheelSeparation>
      <wheelDiameter>0.08</wheelDiameter>
      <broadcastTF>1</broadcastTF>
      <wheelTorque>30</wheelTorque>
      <wheelAcceleration>1.8</wheelAcceleration>
      <commandTopic>cmd_vel</commandTopic>
      <odometryFrame>odom</odometryFrame>
      <odometryTopic>odom</odometryTopic>
      <robotBaseFrame>base_link</robotBaseFrame>
    </plugin>
  </gazebo> -->
    <gazebo>
        <plugin name="skid_steer_drive_controller" filename="libgazebo_ros_skid_steer_drive.so">
        <updateRate>100.0</updateRate>
        <robotNamespace>/</robotNamespace>
        <leftFrontJoint>front_left_wheel_joint</leftFrontJoint>
        <rightFrontJoint>front_right_wheel_joint</rightFrontJoint>
        <leftRearJoint>hind_left_wheel_joint</leftRearJoint>
        <rightRearJoint>hind_right_wheel_joint</rightRearJoint>
        <wheelSeparation>0.4</wheelSeparation>
        <wheelDiameter>0.215</wheelDiameter>
        <robotBaseFrame>base_link</robotBaseFrame>
        <torque>20</torque>
        <topicName>cmd_vel</topicName>
        <broadcastTF>true</broadcastTF>
        <odometryFrame>odom</odometryFrame>
        <odometryTopic>odom</odometryTopic>
        </plugin>
    </gazebo>
    

</robot> 
